2022/09/22 11:36:47 - Terminal_Log - INFO      - log_save.py : 22 line - run the section pre_step
2022/09/22 11:38:47 - Terminal_Log - INFO      - log_save.py : 22 line - run the section pre_step
2022/09/22 11:38:47 - Terminal_Log - INFO      - log_save.py : 22 line - run commnad:  mkdir -p /home/BKCPkg/domains/virtualization
2022/09/22 11:38:48 - Terminal_Log - INFO      - log_save.py : 22 line - out:  

2022/09/22 11:38:48 - Terminal_Log - ERROR     - log_save.py : 28 line - err:  

2022/09/22 11:38:48 - Terminal_Log - INFO      - log_save.py : 22 line - run commnad:  mkdir -p /home/BKCPkg/domains/virtualization/imgs
2022/09/22 11:38:48 - Terminal_Log - INFO      - log_save.py : 22 line - out:  

2022/09/22 11:38:48 - Terminal_Log - ERROR     - log_save.py : 28 line - err:  

2022/09/22 11:38:49 - Terminal_Log - INFO      - log_save.py : 22 line - run commnad:  mkdir -p /home/BKCPkg/domains/virtualization/tools
2022/09/22 11:38:49 - Terminal_Log - INFO      - log_save.py : 22 line - out:  

2022/09/22 11:38:49 - Terminal_Log - ERROR     - log_save.py : 28 line - err:  

2022/09/22 11:38:49 - Terminal_Log - INFO      - log_save.py : 22 line - run commnad:  mkdir -p /home/BKCPkg/domains/virtualization/vt_sut_linux_tools
2022/09/22 11:38:50 - Terminal_Log - INFO      - log_save.py : 22 line - out:  

2022/09/22 11:38:50 - Terminal_Log - ERROR     - log_save.py : 28 line - err:  

2022/09/22 11:38:50 - Terminal_Log - INFO      - log_save.py : 22 line - run commnad:  mkdir -p /home/BKCPkg/domains/virtualization/virtualization_inband
2022/09/22 11:38:50 - Terminal_Log - INFO      - log_save.py : 22 line - out:  

2022/09/22 11:38:50 - Terminal_Log - ERROR     - log_save.py : 28 line - err:  

2022/09/22 11:38:51 - Terminal_Log - INFO      - log_save.py : 22 line - run commnad:  rm -rf /usr/bin/python; ln -s /usr/bin/python3.6 /usr/bin/python
2022/09/22 11:38:51 - Terminal_Log - INFO      - log_save.py : 22 line - out:  

2022/09/22 11:38:51 - Terminal_Log - ERROR     - log_save.py : 28 line - err:  

2022/09/22 11:38:51 - Terminal_Log - INFO      - log_save.py : 22 line - run commnad:  rm -rf /usr/bin/pip;ln -s /usr/bin/pip3.6 /usr/bin/pip
2022/09/22 11:38:52 - Terminal_Log - INFO      - log_save.py : 22 line - out:  

2022/09/22 11:38:52 - Terminal_Log - ERROR     - log_save.py : 28 line - err:  

2022/09/22 11:38:52 - Terminal_Log - INFO      - log_save.py : 22 line - run commnad:  mkdir -p /etc/yum.repos.d/repos.bak; mv /etc/yum.repos.d/*.repo /etc/yum.repos.d/repos.bak
2022/09/22 11:38:52 - Terminal_Log - INFO      - log_save.py : 22 line - out:  

2022/09/22 11:38:52 - Terminal_Log - ERROR     - log_save.py : 28 line - err: mv: cannot stat '/etc/yum.repos.d/*.repo': No such file or directory
 

2022/09/22 11:38:53 - Terminal_Log - INFO      - log_save.py : 22 line - run commnad:  export http_proxy=http://proxy-iind.intel.com:911; export https_proxy=http://proxy-iind.intel.com:911; python -m pip install --upgrade pip
2022/09/22 11:38:54 - Terminal_Log - INFO      - log_save.py : 22 line - out: Requirement already satisfied: pip in /usr/local/lib/python3.6/site-packages (21.3.1)
 

2022/09/22 11:38:54 - Terminal_Log - ERROR     - log_save.py : 28 line - err: WARNING: Running pip as the 'root' user can result in broken permissions and conflicting behaviour with the system package manager. It is recommended to use a virtual environment instead: https://pip.pypa.io/warnings/venv
 

