2022/09/22 12:21:20 - Terminal_Log - INFO      - log_save.py : 22 line - run the section pre_step
2022/09/22 12:21:20 - Terminal_Log - INFO      - log_save.py : 22 line - run commnad:  mkdir -p /home/BKCPkg/domains/virtualization
2022/09/22 12:21:20 - Terminal_Log - INFO      - log_save.py : 22 line - out:  

2022/09/22 12:21:20 - Terminal_Log - ERROR     - log_save.py : 28 line - err:  

2022/09/22 12:21:21 - Terminal_Log - INFO      - log_save.py : 22 line - run commnad:  mkdir -p /home/BKCPkg/domains/virtualization/imgs
2022/09/22 12:21:21 - Terminal_Log - INFO      - log_save.py : 22 line - out:  

2022/09/22 12:21:21 - Terminal_Log - ERROR     - log_save.py : 28 line - err:  

2022/09/22 12:21:21 - Terminal_Log - INFO      - log_save.py : 22 line - run commnad:  mkdir -p /home/BKCPkg/domains/virtualization/tools
2022/09/22 12:21:22 - Terminal_Log - INFO      - log_save.py : 22 line - out:  

2022/09/22 12:21:22 - Terminal_Log - ERROR     - log_save.py : 28 line - err:  

2022/09/22 12:21:22 - Terminal_Log - INFO      - log_save.py : 22 line - run commnad:  mkdir -p /home/BKCPkg/domains/virtualization/vt_sut_linux_tools
2022/09/22 12:21:22 - Terminal_Log - INFO      - log_save.py : 22 line - out:  

2022/09/22 12:21:22 - Terminal_Log - ERROR     - log_save.py : 28 line - err:  

2022/09/22 12:21:23 - Terminal_Log - INFO      - log_save.py : 22 line - run commnad:  mkdir -p /home/BKCPkg/domains/virtualization/virtualization_inband
2022/09/22 12:21:23 - Terminal_Log - INFO      - log_save.py : 22 line - out:  

2022/09/22 12:21:23 - Terminal_Log - ERROR     - log_save.py : 28 line - err:  

2022/09/22 12:21:23 - Terminal_Log - INFO      - log_save.py : 22 line - run commnad:  rm -rf /usr/bin/python; ln -s /usr/bin/python3.6 /usr/bin/python
2022/09/22 12:21:24 - Terminal_Log - INFO      - log_save.py : 22 line - out:  

2022/09/22 12:21:24 - Terminal_Log - ERROR     - log_save.py : 28 line - err:  

2022/09/22 12:21:24 - Terminal_Log - INFO      - log_save.py : 22 line - run commnad:  rm -rf /usr/bin/pip;ln -s /usr/bin/pip3.6 /usr/bin/pip
2022/09/22 12:21:24 - Terminal_Log - INFO      - log_save.py : 22 line - out:  

2022/09/22 12:21:24 - Terminal_Log - ERROR     - log_save.py : 28 line - err:  

2022/09/22 12:21:25 - Terminal_Log - INFO      - log_save.py : 22 line - run commnad:  export http_proxy=http://proxy-iind.intel.com:911; export https_proxy=http://proxy-iind.intel.com:911; python -m pip install --upgrade pip
2022/09/22 12:21:26 - Terminal_Log - INFO      - log_save.py : 22 line - out: Requirement already satisfied: pip in /usr/local/lib/python3.6/site-packages (21.3.1)
 

2022/09/22 12:21:26 - Terminal_Log - ERROR     - log_save.py : 28 line - err: WARNING: Running pip as the 'root' user can result in broken permissions and conflicting behaviour with the system package manager. It is recommended to use a virtual environment instead: https://pip.pypa.io/warnings/venv
 

2022/09/22 12:21:27 - Terminal_Log - INFO      - log_save.py : 22 line - run commnad:  mkdir -p /etc/yum.repos.d/repos.bak; mv /etc/yum.repos.d/*.repo /etc/yum.repos.d/repos.bak
2022/09/22 12:21:27 - Terminal_Log - INFO      - log_save.py : 22 line - out:  

2022/09/22 12:21:27 - Terminal_Log - ERROR     - log_save.py : 28 line - err:  

2022/09/22 12:21:28 - Terminal_Log - INFO      - log_save.py : 22 line - cp ../FILES/Centos-8.repo to /etc/yum.repos.d/Centos-8.repo
2022/09/22 12:21:28 - Terminal_Log - INFO      - log_save.py : 22 line - cp done

2022/09/22 12:21:28 - Terminal_Log - INFO      - log_save.py : 22 line - run commnad:  export http_proxy=http://proxy-iind.intel.com:911; export https_proxy=http://proxy-iind.intel.com:911; yum update -y
2022/09/22 12:21:33 - Terminal_Log - INFO      - log_save.py : 22 line - out: CentOS-8 - Base                                 3.0 kB/s | 3.9 kB     00:01    
CentOS-8 - AppStream                            4.3 kB/s | 4.3 kB     00:01    
CentOS-8 Extra Packages - x86_64                3.2 kB/s | 4.7 kB     00:01    
Dependencies resolved.
Nothing to do.
Complete!
 

2022/09/22 12:21:33 - Terminal_Log - ERROR     - log_save.py : 28 line - err:  

